<?xml version="1.0" encoding="utf-8"?>
<!-- This URDF was automatically created by SolidWorks to URDF Exporter! Originally created by Stephen Brawner (brawner@gmail.com) 
     Commit Version: 1.6.0-1-g15f4949  Build Version: 1.6.7594.29634
     For more information, please see http://wiki.ros.org/sw_urdf_exporter -->
<robot
  name="irb140">
  <link
    name="base_link">
    <inertial>
      <origin
        xyz="-0.082039 0.00040203 0.059925"
        rpy="0 0 0" />
      <mass
        value="96.79" />
      <inertia
        ixx="0.81512"
        ixy="-7.8406E-05"
        ixz="0.057274"
        iyy="1.3048"
        iyz="0.0065755"
        izz="1.9226" />
    </inertial>
    <visual>
      <origin
        xyz="0 0 0"
        rpy="0 0 0" />
      <geometry>
        <mesh
          filename="package://abb_irb140_config/meshes/link_1.STL" />
      </geometry>
      <material
        name="">
        <color
          rgba="0.8902 0.41176 0.12549 1" />
      </material>
    </visual>
    <collision>
      <origin
        xyz="0 0 0"
        rpy="0 0 0" />
      <geometry>
        <mesh
          filename="package://abb_irb140_config/meshes/link_1.STL" />
      </geometry>
    </collision>
  </link>
  <link
    name="link_2">
    <inertial>
      <origin
        xyz="0.028339 0.042934 0.1749"
        rpy="0 0 0" />
      <mass
        value="127.76" />
      <inertia
        ixx="1.7425"
        ixy="-0.13653"
        ixz="-0.31289"
        iyy="1.4176"
        iyz="-0.172"
        izz="1.3947" />
    </inertial>
    <visual>
      <origin
        xyz="0 0 0"
        rpy="0 0 0" />
      <geometry>
        <mesh
          filename="package://abb_irb140_config/meshes/link_2.STL" />
      </geometry>
      <material
        name="">
        <color
          rgba="0.8902 0.41176 0.12549 1" />
      </material>
    </visual>
    <collision>
      <origin
        xyz="0 0 0"
        rpy="0 0 0" />
      <geometry>
        <mesh
          filename="package://abb_irb140_config/meshes/link_2.STL" />
      </geometry>
    </collision>
  </link>
  <joint
    name="joint_1"
    type="continuous">
    <origin
      xyz="0 0 0.0903"
      rpy="0 0 0" />
    <parent
      link="base_link" />
    <child
      link="link_2" />
    <axis
      xyz="0 0 1" />
  </joint>
  <link
    name="link_3">
    <inertial>
      <origin
        xyz="-0.0089688 -0.092434 0.19832"
        rpy="0 0 0" />
      <mass
        value="59.127" />
      <inertia
        ixx="1.2146"
        ixy="0.0045622"
        ixz="-0.017575"
        iyy="1.0257"
        iyz="0.14021"
        izz="0.35063" />
    </inertial>
    <visual>
      <origin
        xyz="0 0 0"
        rpy="0 0 0" />
      <geometry>
        <mesh
          filename="package://abb_irb140_config/meshes/link_3.STL" />
      </geometry>
      <material
        name="">
        <color
          rgba="0.8902 0.41176 0.12549 1" />
      </material>
    </visual>
    <collision>
      <origin
        xyz="0 0 0"
        rpy="0 0 0" />
      <geometry>
        <mesh
          filename="package://abb_irb140_config/meshes/link_3.STL" />
      </geometry>
    </collision>
  </link>
  <joint
    name="joint_2"
    type="continuous">
    <origin
      xyz="0.07 0 0.263"
      rpy="0 0 0" />
    <parent
      link="link_2" />
    <child
      link="link_3" />
    <axis
      xyz="0 1 0" />
  </joint>
  <link
    name="link_4">
    <inertial>
      <origin
        xyz="0.019583 0.0070079 -0.0056775"
        rpy="0 0 0" />
      <mass
        value="62.639" />
      <inertia
        ixx="0.24949"
        ixy="0.022227"
        ixz="0.014419"
        iyy="0.70079"
        iyz="0.0028359"
        izz="0.63695" />
    </inertial>
    <visual>
      <origin
        xyz="0 0 0"
        rpy="0 0 0" />
      <geometry>
        <mesh
          filename="package://abb_irb140_config/meshes/link_4.STL" />
      </geometry>
      <material
        name="">
        <color
          rgba="0.8902 0.41176 0.12549 1" />
      </material>
    </visual>
    <collision>
      <origin
        xyz="0 0 0"
        rpy="0 0 0" />
      <geometry>
        <mesh
          filename="package://abb_irb140_config/meshes/link_4.STL" />
      </geometry>
    </collision>
  </link>
  <joint
    name="joint_3"
    type="continuous">
    <origin
      xyz="0.0013778 0 0.36"
      rpy="0 0 0" />
    <parent
      link="link_3" />
    <child
      link="link_4" />
    <axis
      xyz="0 1 0" />
  </joint>
  <link
    name="link_5">
    <inertial>
      <origin
        xyz="0.093068 -0.0012122 -0.0014339"
        rpy="0 0 0" />
      <mass
        value="13.808" />
      <inertia
        ixx="0.025879"
        ixy="0.00075357"
        ixz="-0.00064679"
        iyy="0.03672"
        iyz="9.774E-06"
        izz="0.042443" />
    </inertial>
    <visual>
      <origin
        xyz="0 0 0"
        rpy="0 0 0" />
      <geometry>
        <mesh
          filename="package://abb_irb140_config/meshes/link_5.STL" />
      </geometry>
      <material
        name="">
        <color
          rgba="0.8902 0.41176 0.12549 1" />
      </material>
    </visual>
    <collision>
      <origin
        xyz="0 0 0"
        rpy="0 0 0" />
      <geometry>
        <mesh
          filename="package://abb_irb140_config/meshes/link_5.STL" />
      </geometry>
    </collision>
  </link>
  <joint
    name="joint_4"
    type="continuous">
    <origin
      xyz="0.2185 -0.0005 0"
      rpy="0 0 0" />
    <parent
      link="link_4" />
    <child
      link="link_5" />
    <axis
      xyz="1 0 0" />
  </joint>
  <link
    name="link_6">
    <inertial>
      <origin
        xyz="-0.0013824 1.8928E-05 -0.00016171"
        rpy="0 0 0" />
      <mass
        value="1.1353" />
      <inertia
        ixx="0.00055166"
        ixy="-1.0646E-06"
        ixz="-1.297E-06"
        iyy="0.00086531"
        iyz="4.5759E-08"
        izz="0.0005335" />
    </inertial>
    <visual>
      <origin
        xyz="0 0 0"
        rpy="0 0 0" />
      <geometry>
        <mesh
          filename="package://abb_irb140_config/meshes/link_6.STL" />
      </geometry>
      <material
        name="">
        <color
          rgba="0.8902 0.41176 0.12549 1" />
      </material>
    </visual>
    <collision>
      <origin
        xyz="0 0 0"
        rpy="0 0 0" />
      <geometry>
        <mesh
          filename="package://abb_irb140_config/meshes/link_6.STL" />
      </geometry>
    </collision>
  </link>
  <joint
    name="joint_5"
    type="continuous">
    <origin
      xyz="0.1615 0 0"
      rpy="0 0 0" />
    <parent
      link="link_5" />
    <child
      link="link_6" />
    <axis
      xyz="0 1 0" />
  </joint>
  <link
    name="link_7">
    <inertial>
      <origin
        xyz="0.029623 5.0678E-10 -0.00022503"
        rpy="0 0 0" />
      <mass
        value="0.20175" />
      <inertia
        ixx="4.6661E-05"
        ixy="2.5845E-12"
        ixz="3.5743E-07"
        iyy="4.8163E-05"
        iyz="5.2731E-12"
        izz="4.9079E-05" />
    </inertial>
    <visual>
      <origin
        xyz="0 0 0"
        rpy="0 0 0" />
      <geometry>
        <mesh
          filename="package://abb_irb140_config/meshes/link_7.STL" />
      </geometry>
      <material
        name="">
        <color
          rgba="0.79608 0.82353 0.93333 1" />
      </material>
    </visual>
    <collision>
      <origin
        xyz="0 0 0"
        rpy="0 0 0" />
      <geometry>
        <mesh
          filename="package://abb_irb140_config/meshes/link_7.STL" />
      </geometry>
    </collision>
  </link>
  <joint
    name="joint_6"
    type="continuous">
    <origin
      xyz="0.02112 -0.00059797 0"
      rpy="0 0 0" />
    <parent
      link="link_6" />
    <child
      link="link_7" />
    <axis
      xyz="1 0 0" />
  </joint>
</robot>
