<?xml version="1.0" ?>
<robot name="abb_irb140" xmlns:xacro="http://ros.org/wiki/xacro">
    <!-- link list -->
    <link name="base_link">
        <visual>
            <origin xyz="0 0 0" rpy="0 0 0"/>
            <geometry>
                <mesh filename="package://abb_irb140_support/meshes/irb140/visual/base_link.stl"/>
            </geometry>
            <material name="abb_orange">
                <color rgba="0.8902 0.41176 0.12549 1"/>
            </material>
        </visual>
        <collision>
            <geometry>
                <mesh filename="package://abb_irb140_support/meshes/irb140/collision/base_link.stl"/>
            </geometry>
            <material name="yellow">
                <color rgba="0 1 1 1"/>
            </material>
        </collision>
    </link>
    <link name="link_1">
    <inertial>
      <origin
        xyz="0.028339 0.042934 0.1749"
        rpy="0 0 0" />
      <mass
        value="35" />
      <inertia
        ixx="0.765"
        ixy="-0.3"
        ixz="0.067"
        iyy="0.31"
        iyz="-0.14"
        izz="0.78" />
    </inertial>
        <visual>
            <origin xyz="0 0 0" rpy="0 0 0"/>
            <geometry>
                <mesh filename="package://abb_irb140_support/meshes/irb140/visual/link_1.stl"/>
            </geometry>
            <material name="abb_orange"/>
        </visual>
        <collision>
            <origin xyz="0 0 0" rpy="0 0 0"/>
            <geometry>
                <mesh filename="package://abb_irb140_support/meshes/irb140/collision/link_1.stl"/>
            </geometry>
            <material name="yellow"/>
        </collision>
    </link>
    <link name="link_2">
    <inertial>
      <origin
        xyz="-0.0089688 -0.092434 0.19829"
        rpy="0 0 0" />
      <mass
        value="25" />
      <inertia
        ixx="1.38"
        ixy="0.045"
        ixz="-0.02"
        iyy="0.364"
        iyz="-0.31"
        izz="1.09" />
    </inertial>
        <visual>
            <origin xyz="0 0 0" rpy="0 0 0"/>
            <geometry>
                <mesh filename="package://abb_irb140_support/meshes/irb140/visual/link_2.stl"/>
            </geometry>
            <material name="abb_orange"/>
        </visual>
        <collision>
            <origin xyz="0 0 0" rpy="0 0 0"/>
            <geometry>
                <mesh filename="package://abb_irb140_support/meshes/irb140/collision/link_2.stl"/>
            </geometry>
            <material name="yellow"/>
        </collision>
    </link>
    <link name="link_3">
    <inertial>
      <origin
        xyz="0.020961 0.0070079 -0.0056775"
        rpy="0 0 0" />
      <mass
        value="18" />
      <inertia
        ixx="0.349"
        ixy="0"
        ixz="0.002"
        iyy="0.338"
        iyz="0.021"
        izz="0.014" />
    </inertial>
        <visual>
            <origin xyz="0 0 0" rpy="0 0 0"/>
            <geometry>
                <mesh filename="package://abb_irb140_support/meshes/irb140/visual/link_3.stl"/>
            </geometry>
            <material name="abb_orange"/>
        </visual>
        <collision>
            <origin xyz="0 0 0" rpy="0 0 0"/>
            <geometry>
                <mesh filename="package://abb_irb140_support/meshes/irb140/collision/link_3.stl"/>
            </geometry>
            <material name="yellow"/>
        </collision>
    </link>
    <link name="link_4">
    <inertial>
      <origin
        xyz="0.094445 -0.0012122 -0.0014339"
        rpy="0 0 0" />
      <mass
        value="6.5" />
      <inertia
        ixx="0.005"
        ixy="0"
        ixz="0"
        iyy="0.011"
        iyz="0"
        izz="0.016" />
    </inertial>
        <visual>
            <origin xyz="0 0 0" rpy="0 0 0"/>
            <geometry>
                <mesh filename="package://abb_irb140_support/meshes/irb140/visual/link_4.stl"/>
            </geometry>
            <material name="abb_orange"/>
        </visual>
        <collision>
            <origin xyz="0 0 0" rpy="0 0 0"/>
            <geometry>
                <mesh filename="package://abb_irb140_support/meshes/irb140/collision/link_4.stl"/>
            </geometry>
            <material name="yellow"/>
        </collision>
    </link>
    <link name="link_5">
    <inertial>
      <origin
        xyz="-0.0013824 1.8928E-05 -0.00016171"
        rpy="0 0 0" />
      <mass
        value="1.5" />
      <inertia
        ixx="0.005"
        ixy="0"
        ixz="0"
        iyy="0.005"
        iyz="4E-05"
        izz="0.0006" />
    </inertial>
        <visual>
            <origin xyz="0 0 0" rpy="0 0 0"/>
            <geometry>
                <mesh filename="package://abb_irb140_support/meshes/irb140/visual/link_5.stl"/>
            </geometry>
            <material name="abb_orange"/>
        </visual>
        <collision>
            <origin xyz="0 0 0" rpy="0 0 0"/>
            <geometry>
                <mesh filename="package://abb_irb140_support/meshes/irb140/collision/link_5.stl"/>
            </geometry>
            <material name="yellow"/>
        </collision>
    </link>
    <link name="link_6">
    <inertial>
      <origin
        xyz="0.040743 -0.00059797 -0.00022503"
        rpy="0 0 0" />
      <mass
        value="0.20175" />
      <inertia
        ixx="4.6661E-05"
        ixy="2.5845E-12"
        ixz="3.5743E-07"
        iyy="4.8163E-05"
        iyz="5.2731E-12"
        izz="4.9079E-05" />
    </inertial>
        <visual>
            <origin xyz="0 0 0" rpy="0 0 0"/>
            <geometry>
                <mesh filename="package://abb_irb140_support/meshes/irb140/visual/link_6.stl"/>
            </geometry>
            <material
              name="abb_gray">
              <color
                rgba="0.79608 0.82353 0.93333 1" />
            </material>
        </visual>
        <collision>
            <origin xyz="0 0 0" rpy="0 0 0"/>
            <geometry>
                <mesh filename="package://abb_irb140_support/meshes/irb140/collision/link_6.stl"/>
            </geometry>
            <material name="yellow"/>
        </collision>
    </link>
    <link name="tool0"/>

    <!-- end of link list -->

    <!-- joint list -->
    <joint name="joint_1" type="revolute">
        <origin xyz="0 0 0.0903" rpy="0 0 0"/>
        <parent link="base_link"/>
        <child link="link_1"/>
        <axis xyz="0 0 1"/>
        <limit lower="-3.1415" upper="3.1415" effort="0" velocity="2.618"/>
    </joint>
    <joint name="joint_2" type="revolute">
        <origin xyz="0.07 0 0.263" rpy="0 0 0"/>
        <parent link="link_1"/>
        <child link="link_2"/>
        <axis xyz="0 1 0"/>
        <limit lower="-1.5708" upper="1.91986" effort="0" velocity="2.618"/>
    </joint>
    <joint name="joint_3" type="revolute">
        <origin xyz="0 0 0.36" rpy="0 0 0"/>
        <parent link="link_2"/>
        <child link="link_3"/>
        <axis xyz="0 1 0"/>
        <limit lower="-4.01426" upper="0.872665" effort="0" velocity="2.618"/>
    </joint>
    <joint name="joint_4" type="revolute">
        <origin xyz="0.2185 0 0" rpy="0 0 0"/>
        <parent link="link_3"/>
        <child link="link_4"/>
        <axis xyz="1 0 0"/>
        <limit lower="-3.49" upper="3.49" effort="0" velocity="6.2832"/>
    </joint>
    <joint name="joint_5" type="revolute">
        <origin xyz="0.1615 0 0" rpy="0 0 0"/>
        <parent link="link_4"/>
        <child link="link_5"/>
        <axis xyz="0 1 0"/>
        <limit lower="-2.00713" upper="2.00713" effort="0" velocity="6.2832"/>
    </joint>
    <joint name="joint_6" type="revolute">
        <origin xyz="0.01 0 0" rpy="0 0 0"/>
        <parent link="link_5"/>
        <child link="link_6"/>
        <axis xyz="1 0 0"/>
        <limit lower="-6.9813" upper="6.9813" effort="0" velocity="7.854"/>
    </joint>
    <joint name="joint_6-tool0" type="fixed">
        <parent link="link_6"/>
        <child link="tool0"/>
        <origin xyz="0.05256 0 0" rpy="0 1.57079632679 0"/>
    </joint>
    <!-- end of joint list -->

    <!-- ROS base_link to ABB World Coordinates transform -->
    <link name="base" />
    <joint name="base_link-base" type="fixed">
        <origin xyz="0 0 0" rpy="0 0 0"/>
        <parent link="base_link"/>
        <child link="base"/>
    </joint>
</robot>

