<?xml version="1.0" encoding="utf-8"?>
<!-- This URDF was automatically created by SolidWorks to URDF Exporter! Originally created by Stephen Brawner (brawner@gmail.com) 
     Commit Version: 1.6.0-1-g15f4949  Build Version: 1.6.7594.29634
     For more information, please see http://wiki.ros.org/sw_urdf_exporter -->
<robot
  name="IRB140_all">
  <link name="world"/>
  <joint name="world_joint" type="fixed">
    <parent link="world"/>
    <child link="base_link"/>
    <origin rpy="0.0 0.0 0.0" xyz="0.0 0.0 0.0903"/>
  </joint>
  <link
    name="base_link">
    <inertial>
      <origin
        xyz="0 0 0"
        rpy="0 0 0" />
      <mass
        value="12" />
      <inertia
        ixx="0"
        ixy="0"
        ixz="0"
        iyy="0"
        iyz="0"
        izz="0" />
    </inertial>
    <visual>
      <geometry>
        <mesh
          filename="package://IRB140_all/meshes/base_link.STL" />
      </geometry>
      <material
        name="abb_yellow">
        <color
          rgba="0.8902 0.41176 0.12549 1" />
      </material>
    </visual>
    <collision>
      <origin
        xyz="1.5708 0 0"
        rpy="0 0 0" />
      <geometry>
        <mesh
          filename="package://IRB140_all/meshes/base_link.STL" />
      </geometry>
    </collision>
  </link>
  <link
    name="L1">
    <inertial>
      <origin
        xyz="0.028339 0.042934 0.1749"
        rpy="0 0 0" />
      <mass
        value="35" />
      <inertia
        ixx="0.765"
        ixy="-0.3"
        ixz="0.067"
        iyy="0.31"
        iyz="-0.14"
        izz="0.78" />
    </inertial>
    <visual>
      <origin
        xyz="0 0 0"
        rpy="0 0 0" />
      <geometry>
        <mesh
          filename="package://IRB140_all/meshes/L1.STL" />
      </geometry>
      <material
        name="abb_yellow">
        <color
          rgba="0.8902 0.41176 0.12549 1" />
      </material>
    </visual>
    <collision>
      <origin
        xyz="0 0 0"
        rpy="0 0 0" />
      <geometry>
        <mesh
          filename="package://IRB140_all/meshes/L1.STL" />
      </geometry>
    </collision>
  </link>
  <joint
    name="J1"
    type="continuous">
    <origin
      xyz="0 0 0"
      rpy="0 0 0" />
    <parent
      link="base_link" />
    <child
      link="L1" />
    <axis
      xyz="0 0 1" />
    <limit
      effort="0"
      velocity="2.618" />
  </joint>
  <link
    name="L2">
    <inertial>
      <origin
        xyz="-0.0089688 -0.092434 0.19829"
        rpy="0 0 0" />
      <mass
        value="25" />
      <inertia
        ixx="1.38"
        ixy="0.045"
        ixz="-0.02"
        iyy="0.364"
        iyz="-0.31"
        izz="1.09" />
    </inertial>
    <visual>
      <origin
        xyz="0 0 0"
        rpy="0 0 0" />
      <geometry>
        <mesh
          filename="package://IRB140_all/meshes/L2.STL" />
      </geometry>
      <material
        name="abb_yellow">
        <color
          rgba="0.8902 0.41176 0.12549 1" />
      </material>
    </visual>
    <collision>
      <origin
        xyz="0 0 0"
        rpy="0 0 0" />
      <geometry>
        <mesh
          filename="package://IRB140_all/meshes/L2.STL" />
      </geometry>
    </collision>
  </link>
  <joint
    name="J2"
    type="revolute">
    <origin
      xyz="0.07 0 0.263"
      rpy="0 0 0" />
    <parent
      link="L1" />
    <child
      link="L2" />
    <axis
      xyz="0 1 0" />
    <limit
      lower="-1.7445"
      upper="1.9199"
      effort="0"
      velocity="2.618" />
  </joint>
  <link
    name="L3">
    <inertial>
      <origin
        xyz="0.020961 0.0070079 -0.0056775"
        rpy="0 0 0" />
      <mass
        value="18" />
      <inertia
        ixx="0.349"
        ixy="0"
        ixz="0.002"
        iyy="0.338"
        iyz="0.021"
        izz="0.014" />
    </inertial>
    <visual>
      <origin
        xyz="0 0 0"
        rpy="0 0 0" />
      <geometry>
        <mesh
          filename="package://IRB140_all/meshes/L3.STL" />
      </geometry>
      <material
        name="abb_yellow">
        <color
          rgba="0.8902 0.41176 0.12549 1" />
      </material>
    </visual>
    <collision>
      <origin
        xyz="0 0 0"
        rpy="0 0 0" />
      <geometry>
        <mesh
          filename="package://IRB140_all/meshes/L3.STL" />
      </geometry>
    </collision>
  </link>
  <joint
    name="J3"
    type="revolute">
    <origin
      xyz="0 0 0.36"
      rpy="0 0 0" />
    <parent
      link="L2" />
    <child
      link="L3" />
    <axis
      xyz="0 1 0" />
    <limit
      lower="-1.0472"
      upper="1.1345"
      effort="0"
      velocity="2.618" />
  </joint>
  <link
    name="L4">
    <inertial>
      <origin
        xyz="0.094445 -0.0012122 -0.0014339"
        rpy="0 0 0" />
      <mass
        value="6.5" />
      <inertia
        ixx="0.005"
        ixy="0"
        ixz="0"
        iyy="0.011"
        iyz="0"
        izz="0.016" />
    </inertial>
    <visual>
      <origin
        xyz="0 0 0"
        rpy="0 0 0" />
      <geometry>
        <mesh
          filename="package://IRB140_all/meshes/L4.STL" />
      </geometry>
      <material
        name="abb_yellow">
        <color
          rgba="0.8902 0.41176 0.12549 1" />
      </material>
    </visual>
    <collision>
      <origin
        xyz="0 0 0"
        rpy="0 0 0" />
      <geometry>
        <mesh
          filename="package://IRB140_all/meshes/L4.STL" />
      </geometry>
    </collision>
  </link>
  <joint
    name="J4"
    type="continuous">
    <origin
      xyz="0.2185 -0.0005 0"
      rpy="0 0 0" />
    <parent
      link="L3" />
    <child
      link="L4" />
    <axis
      xyz="1 0 0" />
    <limit
      effort="0"
      velocity="6.282" />
  </joint>
  <link
    name="L5">
    <inertial>
      <origin
        xyz="-0.0013824 1.8928E-05 -0.00016171"
        rpy="0 0 0" />
      <mass
        value="1.5" />
      <inertia
        ixx="0.005"
        ixy="0"
        ixz="0"
        iyy="0.005"
        iyz="4E-05"
        izz="0.0006" />
    </inertial>
    <visual>
      <origin
        xyz="0 0 0"
        rpy="0 0 0" />
      <geometry>
        <mesh
          filename="package://IRB140_all/meshes/L5.STL" />
      </geometry>
      <material
        name="abb_yellow">
        <color
          rgba="0.8902 0.41176 0.12549 1" />
      </material>
    </visual>
    <collision>
      <origin
        xyz="0 0 0"
        rpy="0 0 0" />
      <geometry>
        <mesh
          filename="package://IRB140_all/meshes/L5.STL" />
      </geometry>
    </collision>
  </link>
  <joint
    name="J5"
    type="revolute">
    <origin
      xyz="0.1615 0 0"
      rpy="0 0 0" />
    <parent
      link="L4" />
    <child
      link="L5" />
    <axis
      xyz="0 1 0" />
    <limit
      lower="-2.0944"
      upper="2.0944"
      effort="0"
      velocity="6.2832" />
  </joint>
  <link
    name="L6">
    <inertial>
      <origin
        xyz="0.040743 -0.00059797 -0.00022503"
        rpy="0 0 0" />
      <mass
        value="0.20175" />
      <inertia
        ixx="4.6661E-05"
        ixy="2.5845E-12"
        ixz="3.5743E-07"
        iyy="4.8163E-05"
        iyz="5.2731E-12"
        izz="4.9079E-05" />
    </inertial>
    <visual>
      <origin
        xyz="0 0 0"
        rpy="0 0 0" />
      <geometry>
        <mesh
          filename="package://IRB140_all/meshes/L6.STL" />
      </geometry>
      <material
        name="abb_gray">
        <color
          rgba="0.79608 0.82353 0.93333 1" />
      </material>
    </visual>
    <collision>
      <origin
        xyz="0 0 0"
        rpy="0 0 0" />
      <geometry>
        <mesh
          filename="package://IRB140_all/meshes/L6.STL" />
      </geometry>
    </collision>
  </link>
  <joint
    name="J6"
    type="continuous">
    <origin
      xyz="0.01 0 0"
      rpy="0 0 0" />
    <parent
      link="L5" />
    <child
      link="L6" />
    <axis
      xyz="1 0 0" />
    <limit
      effort="0"
      velocity="6.2832" />
  </joint>
  <link name="tool0"/>
  <joint name="ee_link" type="fixed">
  <origin
	xyz="0.05256 0 0"
	rpy="0 1.570796326794897 0"/>
	<parent link="L6"/>
	<child link="tool0"/>
  </joint>
</robot>
